Workbook

Sheet TimberFasteners
A1: Type | B1: Producer | C1: Product | D1: Detailinformation | E1: Highest service class | F1: d | G1: l | H1: dh | I1: My,Rk [Nm] | J1: faxk[N/mm^2] | K1: fhead,k[N/mm^2] | L1: ftens,k[kN] | M1: l1 | N1: l3 | O1: f_uk | P1: Bmax
A2: Nail | B2: STRONGTIE | C2: FIRK | D2: Skarpkantspiker | E2: 3 | F2: 2 | G2: 50 | H2: 5 | I2: ='Strongtie Nails'!J2 -> 1.289 | J2: ='Strongtie Nails'!K2 -> 2.5 | K2: ='Strongtie Nails'!L2 -> 8.6 | L2: ='Strongtie Nails'!M2 -> 0
A3: Nail | B3: STRONGTIE | C3: FIRKS | D3: Skarpkantspiker | E3: 3 | F3: 2.3 | G3: 60 | H3: 5.4 | I3: ='Strongtie Nails'!J4 -> 2.566 | J3: ='Strongtie Nails'!K4 -> 2.5 | K3: ='Strongtie Nails'!L4 -> 8.6 | L3: ='Strongtie Nails'!M4 -> 0
A4: Nail | B4: STRONGTIE | C4: FIRKS | D4: Skarpkantspiker | E4: 3 | F4: 2.8 | G4: 75 | H4: 6.4 | I4: ='Strongtie Nails'!J5 -> 4.144 | J4: ='Strongtie Nails'!K5 -> 2.5 | K4: ='Strongtie Nails'!L5 -> 8.6 | L4: ='Strongtie Nails'!M5 -> 0
A5: Nail | B5: STRONGTIE | C5: FIRKSQG | D5: Firkantspiker | E5: 3 | F5: 2.5 | G5: 65 | H5: 6 | I5: ='Strongtie Nails'!J13 -> 3.3 | J5: ='Strongtie Nails'!K13 -> 2.5 | K5: ='Strongtie Nails'!L13 -> 8.6 | L5: ='Strongtie Nails'!M13 -> 0
A6: Nail | B6: STRONGTIE | C6: FIRKSQG | D6: Firkantspiker | E6: 3 | F6: 2.8 | G6: 65 | H6: 6.8 | I6: ='Strongtie Nails'!J14 -> 4.3 | J6: ='Strongtie Nails'!K14 -> 2.5 | K6: ='Strongtie Nails'!L14 -> 8.6 | L6: ='Strongtie Nails'!M14 -> 0
A7: Nail | B7: STRONGTIE | C7: FIRKSQG | D7: Firkantspiker | E7: 3 | F7: 2.8 | G7: 75 | H7: 6.8 | I7: ='Strongtie Nails'!J15 -> 4.3 | J7: ='Strongtie Nails'!K15 -> 2.5 | K7: ='Strongtie Nails'!L15 -> 8.6 | L7: ='Strongtie Nails'!M15 -> 0
A8: Nail | B8: STRONGTIE | C8: FIRKSQG | D8: Firkantspiker | E8: 3 | F8: 2.8 | G8: 90 | H8: 6.8 | I8: ='Strongtie Nails'!J16 -> 4.3 | J8: ='Strongtie Nails'!K16 -> 2.5 | K8: ='Strongtie Nails'!L16 -> 8.6 | L8: ='Strongtie Nails'!M16 -> 0
A9: Nail | B9: STRONGTIE | C9: FIRKSQG | D9: Firkantspiker | E9: 3 | F9: 3.4 | G9: 95 | H9: 7.6 | I9: ='Strongtie Nails'!J17 -> 7 | J9: ='Strongtie Nails'!K17 -> 2.5 | K9: ='Strongtie Nails'!L17 -> 8.6 | L9: ='Strongtie Nails'!M17 -> 0
A10: Nail | B10: STRONGTIE | C10: FIRKSQG | D10: Firkantspiker | E10: 3 | F10: 3.8 | G10: 125 | H10: 8 | I10: ='Strongtie Nails'!J18 -> 13.7 | J10: ='Strongtie Nails'!K18 -> 2.5 | K10: ='Strongtie Nails'!L18 -> 8.6 | L10: ='Strongtie Nails'!M18 -> 0
A11: Nail | B11: STRONGTIE | C11: FIRKSQG | D11: Firkantspiker | E11: 3 | F11: 4.2 | G11: 125 | H11: 8.7 | I11: ='Strongtie Nails'!J19 -> 15.1 | J11: ='Strongtie Nails'!K19 -> 2.5 | K11: ='Strongtie Nails'!L19 -> 8.6 | L11: ='Strongtie Nails'!M19 -> 0
A12: Nail | B12: STRONGTIE | C12: FIRKSQG | D12: Firkantspiker | E12: 3 | F12: 4.8 | G12: 150 | H12: 10 | I12: ='Strongtie Nails'!J20 -> 29.3 | J12: ='Strongtie Nails'!K20 -> 2.5 | K12: ='Strongtie Nails'!L20 -> 8.6 | L12: ='Strongtie Nails'!M20 -> 0
A13: Nail | B13: STRONGTIE | C13: FIRKSQG | D13: Firkantspiker | E13: 3 | F13: 5.5 | G13: 175 | H13: 11.5 | I13: ='Strongtie Nails'!J21 -> 34 | J13: ='Strongtie Nails'!K21 -> 2.5 | K13: ='Strongtie Nails'!L21 -> 8.6 | L13: ='Strongtie Nails'!M21 -> 0
A14: Nail | B14: STRONGTIE | C14: FIRKSQG | D14: Firkantspiker | E14: 3 | F14: 6 | G14: 190 | H14: 13 | I14: ='Strongtie Nails'!J22 -> 35.1 | J14: ='Strongtie Nails'!K22 -> 2.5 | K14: ='Strongtie Nails'!L22 -> 8.6 | L14: ='Strongtie Nails'!M22 -> 0
A15: Nail | B15: STRONGTIE | C15: FIRKSQU | D15: Firkantspiker | E15: 1 | F15: 2.5 | G15: 65 | H15: 6 | I15: ='Strongtie Nails'!J25 -> 3.3 | J15: ='Strongtie Nails'!K25 -> 2.5 | K15: ='Strongtie Nails'!L25 -> 8.6 | L15: ='Strongtie Nails'!M25 -> 0
A16: Nail | B16: STRONGTIE | C16: FIRKSQU | D16: Firkantspiker | E16: 1 | F16: 2.8 | G16: 75 | H16: 6.8 | I16: ='Strongtie Nails'!J26 -> 4.3 | J16: ='Strongtie Nails'!K26 -> 2.5 | K16: ='Strongtie Nails'!L26 -> 8.6 | L16: ='Strongtie Nails'!M26 -> 0
A17: Nail | B17: STRONGTIE | C17: FIRKSQU | D17: Firkantspiker | E17: 1 | F17: 3.4 | G17: 95 | H17: 7.6 | I17: ='Strongtie Nails'!J27 -> 7 | J17: ='Strongtie Nails'!K27 -> 2.5 | K17: ='Strongtie Nails'!L27 -> 8.6 | L17: ='Strongtie Nails'!M27 -> 0
A18: Nail | B18: STRONGTIE | C18: BASN | D18: Stavspiker | E18: 3 | F18: 2.8 | G18: 49.5 | H18: 6.6 | I18: ='Strongtie Nails'!J37 -> 2.6 | J18: ='Strongtie Nails'!K37 -> 4.9 | K18: ='Strongtie Nails'!L37 -> 22.6 | L18: ='Strongtie Nails'!M37 -> 4
A19: Nail | B19: STRONGTIE | C19: BASN | D19: Stavspiker | E19: 3 | F19: 2.8 | G19: 54.5 | H19: 6.6 | I19: ='Strongtie Nails'!J38 -> 2.6 | J19: ='Strongtie Nails'!K38 -> 4.9 | K19: ='Strongtie Nails'!L38 -> 22.6 | L19: ='Strongtie Nails'!M38 -> 4
A20: Nail | B20: STRONGTIE | C20: BASN | D20: Stavspiker | E20: 3 | F20: 2.8 | G20: 63.5 | H20: 6.6 | I20: ='Strongtie Nails'!J39 -> 2.6 | J20: ='Strongtie Nails'!K39 -> 4.9 | K20: ='Strongtie Nails'!L39 -> 22.6 | L20: ='Strongtie Nails'!M39 -> 4
A21: Nail | B21: STRONGTIE | C21: BASN | D21: Stavspiker | E21: 3 | F21: 2.8 | G21: 73.5 | H21: 6.6 | I21: ='Strongtie Nails'!J40 -> 2.6 | J21: ='Strongtie Nails'!K40 -> 4.9 | K21: ='Strongtie Nails'!L40 -> 22.6 | L21: ='Strongtie Nails'!M40 -> 4
A22: Nail | B22: STRONGTIE | C22: BASN | D22: Stavspiker | E22: 3 | F22: 3 | G22: 88 | H22: 6.6 | I22: ='Strongtie Nails'!J41 -> 3.9 | J22: ='Strongtie Nails'!K41 -> 5.4 | K22: ='Strongtie Nails'!L41 -> 20.9 | L22: ='Strongtie Nails'!M41 -> 4.8
A23: Nail | B23: STRONGTIE | C23: FIRKD | D23: Stavspiker | E23: 3 | F23: 2.8 | G23: 64 | H23: 11.5 | I23: ='Strongtie Nails'!J42 -> 3.7 | J23: ='Strongtie Nails'!K42 -> 2.5 | K23: ='Strongtie Nails'!L42 -> 20.5 | L23: ='Strongtie Nails'!M42 -> 0
A24: Nail | B24: STRONGTIE | C24: FIRKD | D24: Stavspiker | E24: 3 | F24: 2.8 | G24: 73 | H24: 11.5 | I24: ='Strongtie Nails'!J43 -> 3.7 | J24: ='Strongtie Nails'!K43 -> 2.5 | K24: ='Strongtie Nails'!L43 -> 20.5 | L24: ='Strongtie Nails'!M43 -> 0
A25: Nail | B25: STRONGTIE | C25: FIRKD | D25: Stavspiker | E25: 3 | F25: 2.8 | G25: 87 | H25: 11.5 | I25: ='Strongtie Nails'!J44 -> 3.7 | J25: ='Strongtie Nails'!K44 -> 2.5 | K25: ='Strongtie Nails'!L44 -> 20.5 | L25: ='Strongtie Nails'!M44 -> 0
A26: Nail | B26: STRONGTIE | C26: RSN | D26: Stavspiker | E26: 1 | F26: 2.8 | G26: 63.5 | H26: 6.2 | I26: ='Strongtie Nails'!J45 -> 3.2 | J26: ='Strongtie Nails'!K45 -> 8.9 | K26: ='Strongtie Nails'!L45 -> 29.4 | L26: ='Strongtie Nails'!M45 -> 3.4
A27: Nail | B27: STRONGTIE | C27: RSN | D27: Stavspiker | E27: 1 | F27: 2.8 | G27: 73.5 | H27: 6.9 | I27: ='Strongtie Nails'!J46 -> 3.2 | J27: ='Strongtie Nails'!K46 -> 8.9 | K27: ='Strongtie Nails'!L46 -> 29.4 | L27: ='Strongtie Nails'!M46 -> 3.4
A28: Nail | B28: STRONGTIE | C28: RSN | D28: Stavspiker | E28: 1 | F28: 3.1 | G28: 88 | H28: 6.9 | I28: ='Strongtie Nails'!J47 -> 4.6 | J28: ='Strongtie Nails'!K47 -> 8.3 | K28: ='Strongtie Nails'!L47 -> 18.1 | L28: ='Strongtie Nails'!M47 -> 3.8
A29: Nail | B29: STRONGTIE | C29: RSN | D29: Stavspiker | E29: 1 | F29: 3.1 | G29: 64.5 | H29: 6.9 | I29: ='Strongtie Nails'!J48 -> 4.6 | J29: ='Strongtie Nails'!K48 -> 8.3 | K29: ='Strongtie Nails'!L48 -> 18.1 | L29: ='Strongtie Nails'!M48 -> 3.8
... A39: Nail | B39: STRONGTIE | C39: RSNC | D39: Coilspiker | E39: 1 | F39: 3.1 | G39: 64.5 | H39: 6.9 | I39: ='Strongtie Nails'!J58 -> 4.6 | J39: ='Strongtie Nails'!K58 -> 8.3 | K39: ='Strongtie Nails'!L58 -> 18.1 | L39: ='Strongtie Nails'!M58 -> 3.8
A40: Screw | B40: STRONGTIE | C40: SDWS | D40: Konstruksjonsskrue, utvendig | E40: 3 | F40: 8 | G40: 75 | H40: 19.4 | I40: 17.4 | J40: 13.2 | K40: 21.4 | L40: 21.4 | M40: 37
A41: Screw | B41: STRONGTIE | C41: SDWS | D41: Konstruksjonsskrue, utvendig | E41: 3 | F41: 8 | G41: 100 | H41: 19.4 | I41: 17.4 | J41: 13.2 | K41: 21.4 | L41: 21.4 | M41: 59
A42: Screw | B42: STRONGTIE | C42: SDWS | D42: Konstruksjonsskrue, utvendig | E42: 3 | F42: 8 | G42: 126 | H42: 19.4 | I42: 17.4 | J42: 13.2 | K42: 21.4 | L42: 21.4 | M42: 69
A43: Screw | B43: STRONGTIE | C43: SDWS | D43: Konstruksjonsskrue, utvendig | E43: 3 | F43: 8 | G43: 151 | H43: 19.4 | I43: 17.4 | J43: 13.2 | K43: 21.4 | L43: 21.4 | M43: 69
A44: Screw | B44: STRONGTIE | C44: SDWS | D44: Konstruksjonsskrue, utvendig | E44: 3 | F44: 8 | G44: 202 | H44: 19.4 | I44: 17.4 | J44: 13.2 | K44: 21.4 | L44: 21.4 | M44: 69
A45: Screw | B45: STRONGTIE | C45: SDWS | D45: Konstruksjonsskrue, utvendig | E45: 3 | F45: 8 | G45: 252 | H45: 19.4 | I45: 17.4 | J45: 13.2 | K45: 21.4 | L45: 21.4 | M45: 69
A46: Screw | B46: STRONGTIE | C46: SWD | D46: Nordisk treskrue, dobbeltgjenget | E46: 2 | F46: 6.5 | G46: 65 | H46: 8 | I46: 14.5 | J46: 13 | K46: 29.4 | L46: 14.3 | M46: 28 | N46: 21.5
A47: Screw | B47: STRONGTIE | C47: SWD | D47: Nordisk treskrue, dobbeltgjenget | E47: 2 | F47: 6.5 | G47: 90 | H47: 8 | I47: 14.5 | J47: 13 | K47: 29.4 | L47: 14.3 | M47: 40 | N47: 33.5
A48: Screw | B48: STRONGTIE | C48: SWD | D48: Nordisk treskrue, dobbeltgjenget | E48: 2 | F48: 6.5 | G48: 130 | H48: 8 | I48: 14.5 | J48: 13 | K48: 29.4 | L48: 14.3 | M48: 40 | N48: 33.5
A49: Screw | B49: STRONGTIE | C49: SWD | D49: Nordisk treskrue, dobbeltgjenget | E49: 2 | F49: 6.5 | G49: 160 | H49: 8 | I49: 14.5 | J49: 13 | K49: 29.4 | L49: 14.3 | M49: 65 | N49: 58.5
...

Sheet Washers
A1: Producer | B1: Type | C1: Usage | D1: rod | E1: d int | F1: d ext | G1: s
A2: ROTHOBLAAS | B2: ULS DIN 9021 | C2: Washer S235 DIN 9021 | D2: 8 | E2: 8.4 | F2: 24 | G2: 2
A3: ROTHOBLAAS | B3: ULS DIN 9021 | C3: Washer S235 DIN 9021 | D3: 10 | E3: 10.5 | F3: 30 | G3: 2.5
A4: ROTHOBLAAS | B4: ULS DIN 9021 | C4: Washer S235 DIN 9021 | D4: 12 | E4: 13 | F4: 37 | G4: 3
A5: ROTHOBLAAS | B5: ULS DIN 9021 | C5: Washer S235 DIN 9021 | D5: 14 | E5: 15 | F5: 44 | G5: 3
A6: ROTHOBLAAS | B6: ULS DIN 9021 | C6: Washer S235 DIN 9021 | D6: 16 | E6: 17 | F6: 50 | G6: 3
A7: ROTHOBLAAS | B7: ULS DIN 9021 | C7: Washer S235 DIN 9021 | D7: 18 | E7: 20 | F7: 56 | G7: 4
A8: ROTHOBLAAS | B8: ULS DIN 9021 | C8: Washer S235 DIN 9021 | D8: 20 | E8: 22 | F8: 60 | G8: 4
A9: ROTHOBLAAS | B9: ULS DIN 440 R | C9: Washer S235 DIN 440 R | D9: 10 | E9: 11 | F9: 34 | G9: 3
A10: ROTHOBLAAS | B10: ULS DIN 440 R | C10: Washer S235 DIN 440 R | D10: 12 | E10: 13.5 | F10: 44 | G10: 4
A11: ROTHOBLAAS | B11: ULS DIN 440 R | C11: Washer S235 DIN 440 R | D11: 16 | E11: 17.5 | F11: 56 | G11: 5
A12: ROTHOBLAAS | B12: ULS DIN 440 R | C12: Washer S235 DIN 440 R | D12: 20 | E12: 22 | F12: 72 | G12: 6
A13: ROTHOBLAAS | B13: ULS DIN 440 R | C13: Washer S235 DIN 440 R | D13: 22 | E13: 24 | F13: 80 | G13: 6
... A34: SCHMID | B34: Washer CS | C34: HBS | D34: 12 | E34: 14 | F34: 37 | G34: 7.5

Sheet BoltGrades
A1: bolt | B1: As,nom | C1: 4.6 | D1: 4.8 | E1: 5.6 | F1: 5.8 | G1: 6.8 | H1: 8.8 | I1: 10.9 | J1: 50 | K1: 70 | L1: 80 | M1: 100
A2: f_ub | C2: 400 | D2: 400 | E2: 500 | F2: 500 | G2: 600 | H2: 800 | I2: 1000 | J2: 500 | K2: 600 | L2: 800 | M2: 1000
A3: f_ub_tab | C3: 400 | D3: 420 | E3: 500 | F3: 520 | G3: 600 | H3: 830 | I3: 1040 | J3: 500 | K3: 700 | L3: 800 | M3: 1000
A4: M5 | B4: 14.2 | C4: =$B$4*C3/1000 -> 5.68 | D4: =$B$4*D3/1000 -> 5.964 | E4: =$B$4*E3/1000 -> 7.1 | F4: =$B$4*F3/1000 -> 7.384 | G4: =$B$4*G3/1000 -> 8.52 | H4: =$B$4*H3/1000 -> 11.786 | I4: =$B$4*I3/1000 -> 14.768 | J4: =$B$4*J3/1000 -> 7.1 | ... M4: =$B$4*M3/1000 -> 14.2
A5: M6 | B5: 20.1 | C5: =$B$5*C3/1000 -> 8.04 | D5: =$B$5*D3/1000 -> 8.442 | E5: =$B$5*E3/1000 -> 10.05 | F5: =$B$5*F3/1000 -> 10.452 | G5: =$B$5*G3/1000 -> 12.06 | H5: =$B$5*H3/1000 -> 16.683 | I5: =$B$5*I3/1000 -> 20.904 | J5: =$B$5*J3/1000 -> 10.05 | ... M5: =$B$5*M3/1000 -> 20.1
A6: M7 | B6: 28.9 | C6: =$B$6*C3/1000 -> 11.56 | D6: =$B$6*D3/1000 -> 12.138 | E6: =$B$6*E3/1000 -> 14.45 | F6: =$B$6*F3/1000 -> 15.028 | G6: =$B$6*G3/1000 -> 17.34 | H6: =$B$6*H3/1000 -> 23.987 | I6: =$B$6*I3/1000 -> 30.056 | J6: =$B$6*J3/1000 -> 14.45 | ... M6: =$B$6*M3/1000 -> 28.9
A7: M8 | B7: 36.6 | C7: =$B$7*C3/1000 -> 14.64 | D7: =$B$7*D3/1000 -> 15.372 | E7: =$B$7*E3/1000 -> 18.3 | F7: =$B$7*F3/1000 -> 19.032 | G7: =$B$7*G3/1000 -> 21.96 | H7: =$B$7*H3/1000 -> 30.378 | I7: =$B$7*I3/1000 -> 38.064 | J7: =$B$7*J3/1000 -> 18.3 | ... M7: =$B$7*M3/1000 -> 36.6
A8: M10 | B8: 58 | C8: =$B$8*C3/1000 -> 23.2 | D8: =$B$8*D3/1000 -> 24.36 | E8: =$B$8*E3/1000 -> 29 | F8: =$B$8*F3/1000 -> 30.16 | G8: =$B$8*G3/1000 -> 34.8 | H8: =$B$8*H3/1000 -> 48.14 | I8: =$B$8*I3/1000 -> 60.32 | J8: =$B$8*J3/1000 -> 29 | ... M8: =$B$8*M3/1000 -> 58
A9: M12 | B9: 84.3 | C9: 33.7 | D9: 35.4 | E9: 42.2 | F9: 43.8 | G9: 50.6 | H9: 70 | I9: 87.7 | J9: 42.2 | K9: 59 | L9: 67.4 | M9: =B9*$M$3/1000 -> 84.3
A10: M14 | B10: 115 | C10: 46 | D10: 48.3 | E10: 57.5 | F10: 59.8 | G10: 69 | H10: 95.5 | I10: 120 | J10: 57.5 | K10: 80.5 | L10: 92 | M10: =B10*$M$3/1000 -> 115
A11: M16 | B11: 157 | C11: 62.8 | D11: 65.9 | E11: 78.5 | F11: 81.6 | G11: 94 | H11: 130 | I11: 163 | J11: 78.5 | K11: 110 | L11: 126 | M11: =B11*$M$3/1000 -> 157
A12: M18 | B12: 192 | C12: 76.8 | D12: 80.6 | E12: 96 | F12: 99.8 | G12: 115 | H12: 159 | I12: 200 | J12: 96 | K12: 134 | L12: 154 | M12: =B12*$M$3/1000 -> 192
A13: M20 | B13: 245 | C13: 98 | D13: 103 | E13: 122 | F13: 127 | G13: 147 | H13: 203 | I13: 255 | J13: 122 | K13: 172 | L13: 196 | M13: =B13*$M$3/1000 -> 245
A14: M22 | B14: 303 | C14: 121 | D14: 127 | E14: 152 | F14: 158 | G14: 182 | H14: 252 | I14: 315 | J14: 152 | K14: 212 | L14: 242 | M14: =B14*$M$3/1000 -> 303
A15: M24 | B15: 353 | C15: 141 | D15: 148 | E15: 176 | F15: 184 | G15: 212 | H15: 293 | I15: 367 | J15: 176 | K15: 247 | L15: 282 | M15: =B15*$M$3/1000 -> 353
A16: M27 | B16: 459 | C16: 184 | D16: 193 | E16: 230 | F16: 239 | G16: 275 | H16: 381 | I16: 477 | J16: 230 | K16: 321 | L16: 367 | M16: =B16*$M$3/1000 -> 459
A17: M30 | B17: 561 | C17: 224 | D17: 236 | E17: 280 | F17: 292 | G17: 337 | H17: 466 | I17: 583 | J17: 280 | K17: 393 | L17: 449 | M17: =B17*$M$3/1000 -> 561
A18: M33 | B18: 694 | C18: 278 | D18: 292 | E18: 347 | F18: 361 | G18: 416 | H18: 576 | I18: 722 | J18: 347 | K18: 486 | L18: 555 | M18: =B18*$M$3/1000 -> 694
A19: M36 | B19: 817 | C19: 327 | D19: 343 | E19: 408 | F19: 425 | G19: 490 | H19: 678 | I19: 850 | J19: 408 | K19: 572 | L19: 654 | M19: =B19*$M$3/1000 -> 817

Sheet DIN 571
A1: Produsent | B1: Type | C1: Usage | D1: Highest service class | E1: d | F1: l | G1: dh | H1: My,Rk [Nm] | I1: faxk[N/mm^2] | J1: fhead,k[N/mm^2] | K1: ftens,k[kN] | L1: l1 | M1: l3
A2: DIN 571 | B2: DIN 571 (4.6) | C2: Fransk treskrue (NKT) | D2: 3 | E2: 6 | F2: 25 | G2: 10 | H2: 4.8 | I2: 15.3 | K2: 7 | L2: =F2*0.6 -> 15
A3: DIN 571 | B3: DIN 571 (4.6) | C3: Fransk treskrue (NKT) | D3: 3 | E3: 6 | F3: 30 | G3: 10 | H3: 4.8 | I3: 15.3 | K3: 7 | L3: =F3*0.6 -> 18
A4: DIN 571 | B4: DIN 571 (4.6) | C4: Fransk treskrue (NKT) | D4: 3 | E4: 6 | F4: 40 | G4: 10 | H4: 4.8 | I4: 15.3 | K4: 7 | L4: =F4*0.6 -> 24
A5: DIN 571 | B5: DIN 571 (4.6) | C5: Fransk treskrue (NKT) | D5: 3 | E5: 6 | F5: 50 | G5: 10 | H5: 4.8 | I5: 15.3 | K5: 7 | L5: =F5*0.6 -> 30
A6: DIN 571 | B6: DIN 571 (4.6) | C6: Fransk treskrue (NKT) | D6: 3 | E6: 6 | F6: 60 | G6: 10 | H6: 4.8 | I6: 15.3 | K6: 7 | L6: =F6*0.6 -> 36
A7: DIN 571 | B7: DIN 571 (4.6) | C7: Fransk treskrue (NKT) | D7: 3 | E7: 6 | F7: 70 | G7: 10 | H7: 4.8 | I7: 15.3 | K7: 7 | L7: =F7*0.6 -> 42
A8: DIN 571 | B8: DIN 571 (4.6) | C8: Fransk treskrue (NKT) | D8: 3 | E8: 6 | F8: 80 | G8: 10 | H8: 4.8 | I8: 15.3 | K8: 7 | L8: =F8*0.6 -> 48
A9: DIN 571 | B9: DIN 571 (4.6) | C9: Fransk treskrue (NKT) | D9: 3 | E9: 6 | F9: 90 | G9: 10 | H9: 4.8 | I9: 15.3 | K9: 7 | L9: =F9*0.6 -> 54
A10: DIN 571 | B10: DIN 571 (4.6) | C10: Fransk treskrue (NKT) | D10: 3 | E10: 6 | F10: 100 | G10: 10 | H10: 4.8 | I10: 15.3 | K10: 7 | L10: =F10*0.6 -> 60
A11: DIN 571 | B11: DIN 571 (4.6) | C11: Fransk treskrue (NKT) | D11: 3 | E11: 8 | F11: 30 | G11: 13 | H11: 10.1 | I11: 12.4 | K11: 11 | L11: =F11*0.6 -> 18
A12: DIN 571 | B12: DIN 571 (4.6) | C12: Fransk treskrue (NKT) | D12: 3 | E12: 8 | F12: 40 | G12: 13 | H12: 10.1 | I12: 12.4 | K12: 11 | L12: =F12*0.6 -> 24
A13: DIN 571 | B13: DIN 571 (4.6) | C13: Fransk treskrue (NKT) | D13: 3 | E13: 8 | F13: 50 | G13: 13 | H13: 10.1 | I13: 12.4 | K13: 11 | L13: =F13*0.6 -> 30
... A62: DIN 571 | B62: DIN 571 (4.6) | C62: Fransk treskrue (NKT) | D62: 3 | E62: 16 | F62: 300 | G62: 24 | H62: 61.6 | I62: 8.4 | K62: 51 | L62: =F62*0.6 -> 180
A63: DIN 571 | B63: DIN 571 (4.8) | C63: Fransk treskrue (INDEX) | D63: 2 | E63: 5 | F63: 30 | G63: 8 | H63: 5.984 | I63: 9.31 | J63: 26.42 | K63: 5.2 | L63: =F63*0.6 -> 18
A64: DIN 571 | B64: DIN 571 (4.8) | C64: Fransk treskrue (INDEX) | D64: 2 | E64: 6 | G64: 10 | H64: 10.749 | I64: 7.73 | J64: 24.9 | K64: 7.4
A65: DIN 571 | B65: DIN 571 (4.8) | C65: Fransk treskrue (INDEX) | D65: 2 | E65: 7 | G65: 12 | H65: 18.047 | I65: 10.33 | J65: 24.74 | K65: 9.1
A66: DIN 571 | B66: DIN 571 (4.8) | C66: Fransk treskrue (INDEX) | D66: 2 | E66: 8 | G66: 13 | H66: 24.131 | I66: 6.72 | J66: 22.55 | K66: 11.8
A67: DIN 571 | B67: DIN 571 (4.8) | C67: Fransk treskrue (INDEX) | D67: 2 | E67: 10 | G67: 17 | H67: 49.056 | I67: 6.71 | J67: 21.37 | K67: 18.9
A68: DIN 571 | B68: DIN 571 (4.8) | C68: Fransk treskrue (INDEX) | D68: 2 | E68: 12 | G68: 19 | H68: 81.096 | I68: 7.62 | J68: 20.15 | K68: 34.2
A69: DIN 571 | B69: DIN 571 (4.8) | C69: Fransk treskrue (INDEX) | D69: 2 | E69: 14 | G69: 22 | H69: 129.198 | I69: 7.05 | J69: 20.23 | K69: 45.2
A70: DIN 571 | B70: DIN 571 (A2) | C70: Fransk treskrue (INDEX) | D70: 3 | E70: 6 | G70: 10 | H70: 14.18 | I70: 13.24 | J70: 24.77 | K70: 12.81
A71: DIN 571 | B71: DIN 571 (A2) | C71: Fransk treskrue (INDEX) | D71: 3 | E71: 8 | G71: 13 | H71: 29.081 | I71: 12.43 | J71: 22.25 | K71: 18.55
A72: DIN 571 | B72: DIN 571 (A2) | C72: Fransk treskrue (INDEX) | D72: 3 | E72: 10 | G72: 17 | H72: 41.348 | I72: 12.23 | J72: 20.76 | K72: 30.12
Y242: 100
Y243: 100
Y244: 100
Y245: 100
Y246: 100
Y247: 100
Y248: 50
Y249: 50
Y250: 50
Y251: 50
Y252: 50
Y253: 50
... Y274: 25

Sheet Dowels
A1: Producer | B1: Product | C1: Detail information | D1: Highest service class | E1: d | F1: l | G1: dh | H1: My,Rk [Nm] | I1: faxk[N/mm^2] | J1: fhead,k[N/mm^2] | K1: ftens,k[kN] | L1: l1 | M1: l3 | N1: f_uk | O1: Bmax
A2: ROTHOBLAAS | B2: STA | C2: Smooth Dowel, S355 | D2: 2 | E2: 20 | F2: 1000 | G2: 20 | H2: 340 | I2: 0 | J2: 0 | K2: 0
A3: ROTHOBLAAS | B3: STA | C3: Smooth Dowel, S355 | D3: 2 | E3: 20 | F3: 400 | G3: 20 | H3: 340 | I3: 0 | J3: 0 | K3: 0
A4: ROTHOBLAAS | B4: STA | C4: Smooth Dowel, S355 | D4: 2 | E4: 20 | F4: 360 | G4: 20 | H4: 340 | I4: 0 | J4: 0 | K4: 0
A5: ROTHOBLAAS | B5: STA | C5: Smooth Dowel, S355 | D5: 2 | E5: 20 | F5: 320 | G5: 20 | H5: 340 | I5: 0 | J5: 0 | K5: 0
A6: ROTHOBLAAS | B6: STA | C6: Smooth Dowel, S355 | D6: 2 | E6: 20 | F6: 300 | G6: 20 | H6: 340 | I6: 0 | J6: 0 | K6: 0
A7: ROTHOBLAAS | B7: STA | C7: Smooth Dowel, S355 | D7: 2 | E7: 20 | F7: 280 | G7: 20 | H7: 340 | I7: 0 | J7: 0 | K7: 0
A8: ROTHOBLAAS | B8: STA | C8: Smooth Dowel, S355 | D8: 2 | E8: 20 | F8: 260 | G8: 20 | H8: 340 | I8: 0 | J8: 0 | K8: 0
A9: ROTHOBLAAS | B9: STA | C9: Smooth Dowel, S355 | D9: 2 | E9: 20 | F9: 240 | G9: 20 | H9: 340 | I9: 0 | J9: 0 | K9: 0
A10: ROTHOBLAAS | B10: STA | C10: Smooth Dowel, S355 | D10: 2 | E10: 20 | F10: 220 | G10: 20 | H10: 340 | I10: 0 | J10: 0 | K10: 0
A11: ROTHOBLAAS | B11: STA | C11: Smooth Dowel, S355 | D11: 2 | E11: 20 | F11: 200 | G11: 20 | H11: 340 | I11: 0 | J11: 0 | K11: 0
A12: ROTHOBLAAS | B12: STA | C12: Smooth Dowel, S355 | D12: 2 | E12: 20 | F12: 190 | G12: 20 | H12: 340 | I12: 0 | J12: 0 | K12: 0
A13: ROTHOBLAAS | B13: STA | C13: Smooth Dowel, S355 | D13: 2 | E13: 20 | F13: 180 | G13: 20 | H13: 340 | I13: 0 | J13: 0 | K13: 0
... A66: ROTHOBLAAS | B66: STA | C66: Smooth Dowel, S235 | D66: 2 | E66: 8 | F66: 60 | G66: 8 | H66: 24.1 | I66: 0 | J66: 0 | K66: 0
A67: ROTHOBLAAS | B67: SBD | C67: Self-drilling dowel | D67: 2 | E67: 7.5 | F67: 235 | G67: 11 | H67: 75 | I67: 0 | J67: 0 | K67: 0 | L67: =F67-15 -> 220 | O67: 240
A68: ROTHOBLAAS | B68: SBD | C68: Self-drilling dowel | D68: 2 | E68: 7.5 | F68: 215 | G68: 11 | H68: 75 | I68: 0 | J68: 0 | K68: 0 | L68: =F68-15 -> 200 | O68: 240
A69: ROTHOBLAAS | B69: SBD | C69: Self-drilling dowel | D69: 2 | E69: 7.5 | F69: 195 | G69: 11 | H69: 75 | I69: 0 | J69: 0 | K69: 0 | L69: =F69-15 -> 180 | O69: 220
A70: ROTHOBLAAS | B70: SBD | C70: Self-drilling dowel | D70: 2 | E70: 7.5 | F70: 175 | G70: 11 | H70: 75 | I70: 0 | J70: 0 | K70: 0 | L70: =F70-15 -> 160 | O70: 200
A71: ROTHOBLAAS | B71: SBD | C71: Self-drilling dowel | D71: 2 | E71: 7.5 | F71: 155 | G71: 11 | H71: 75 | I71: 0 | J71: 0 | K71: 0 | L71: =F71-15 -> 140 | O71: 180
A72: ROTHOBLAAS | B72: SBD | C72: Self-drilling dowel | D72: 2 | E72: 7.5 | F72: 135 | G72: 11 | H72: 75 | I72: 0 | J72: 0 | K72: 0 | L72: =F72-15 -> 120 | O72: 160
A73: ROTHOBLAAS | B73: SBD | C73: Self-drilling dowel | D73: 2 | E73: 7.5 | F73: 115 | G73: 11 | H73: 75 | I73: 0 | J73: 0 | K73: 0 | L73: =F73-15 -> 100 | O73: 140
A74: ROTHOBLAAS | B74: SBD | C74: Self-drilling dowel | D74: 2 | E74: 7.5 | F74: 95 | G74: 11 | H74: 75 | I74: 0 | J74: 0 | K74: 0 | L74: =F74-15 -> 80 | O74: 120
A75: ROTHOBLAAS | B75: SBD short | C75: Self-drilling dowel | D75: 2 | E75: 7.5 | F75: 75 | G75: 11 | H75: 42 | I75: 0 | J75: 0 | K75: 0 | L75: =F75-8 -> 67 | O75: 100
A76: ROTHOBLAAS | B76: SBD short | C76: Self-drilling dowel | D76: 2 | E76: 7.5 | F76: 55 | G76: 11 | H76: 42 | I76: 0 | J76: 0 | K76: 0 | L76: =F76-8 -> 47 | O76: 80
A77: EN 1.4404 | B77: AISI 316L | C77: Stainless steel round bar, fuk 520 Mpa | D77: 3 | E77: 8 | F77: 1000 | G77: 8 | H77: =0.3*520*E77^2.6/1000 -> 34.766307 | I77: 0 | J77: 0 | K77: 0
A78: EN 1.4404 | B78: AISI 316L | C78: Stainless steel round bar, fuk 520 Mpa | D78: 3 | E78: 10 | F78: 1000 | G78: 10 | H78: =0.3*520*E78^2.6/1000 -> 62.104719 | I78: 0 | J78: 0 | K78: 0
A79: EN 1.4404 | B79: AISI 316L | C79: Stainless steel round bar, fuk 520 Mpa | D79: 3 | E79: 12 | F79: 1000 | G79: 12 | H79: =0.3*520*E79^2.6/1000 -> 99.76905 | I79: 0 | J79: 0 | K79: 0
A80: EN 1.4404 | B80: AISI 316L | C80: Stainless steel round bar, fuk 520 Mpa | D80: 3 | E80: 16 | F80: 1000 | G80: 16 | H80: =0.3*520*E80^2.6/1000 -> 210.78347 | I80: 0 | J80: 0 | K80: 0
A81: EN 1.4404 | B81: AISI 316L | C81: Stainless steel round bar, fuk 520 Mpa | D81: 3 | E81: 20 | F81: 1000 | G81: 20 | H81: =0.3*520*E81^2.6/1000 -> 376.5326 | I81: 0 | J81: 0 | K81: 0
A82: EN 1.4404 | B82: AISI 316L | C82: Stainless steel round bar, fuk 520 Mpa | D82: 3 | E82: 22 | F82: 1000 | G82: 22 | H82: =0.3*520*E82^2.6/1000 -> 482.41807 | I82: 0 | J82: 0 | K82: 0
A83: EN 1.4404 | B83: AISI 316L | C83: Stainless steel round bar, fuk 520 Mpa | D83: 3 | E83: 25 | F83: 1000 | G83: 25 | H83: =0.3*520*E83^2.6/1000 -> 672.61821 | I83: 0 | J83: 0 | K83: 0
A84: EN 1.4301 | B84: AISI 304 | C84: Stainless steel round bar, fuk 520 Mpa | D84: 3 | E84: 10 | F84: 1000 | G84: 10 | H84: =0.3*520*E84^2.6/1000 -> 62.104719 | I84: 0 | J84: 0 | K84: 0
A85: EN 1.4301 | B85: AISI 304 | C85: Stainless steel round bar, fuk 520 Mpa | D85: 3 | E85: 12 | F85: 1000 | G85: 12 | H85: =0.3*520*E85^2.6/1000 -> 99.76905 | I85: 0 | J85: 0 | K85: 0
A86: EN 1.4301 | B86: AISI 304 | C86: Stainless steel round bar, fuk 520 Mpa | D86: 3 | E86: 13 | F86: 1000 | G86: 13 | H86: =0.3*520*E86^2.6/1000 -> 122.85061 | I86: 0 | J86: 0 | K86: 0
A87: EN 1.4301 | B87: AISI 304 | C87: Stainless steel round bar, fuk 520 Mpa | D87: 3 | E87: 16 | F87: 1000 | G87: 16 | H87: =0.3*520*E87^2.6/1000 -> 210.78347 | I87: 0 | J87: 0 | K87: 0
A88: EN 1.4301 | B88: AISI 304 | C88: Stainless steel round bar, fuk 520 Mpa | D88: 3 | E88: 20 | F88: 1000 | G88: 20 | H88: =0.3*520*E88^2.6/1000 -> 376.5326 | I88: 0 | J88: 0 | K88: 0
A89: EN 1.4301 | B89: AISI 304 | C89: Stainless steel round bar, fuk 520 Mpa | D89: 3 | E89: 25 | F89: 1000 | G89: 25 | H89: =0.3*520*E89^2.6/1000 -> 672.61821 | I89: 0 | J89: 0 | K89: 0
A90: NS-EN 10025-2 | B90: S 235 | C90: fuk 360 Mpa | D90: 2 | E90: 7 | F90: 1000 | G90: 7 | H90: =0.3*360*E90^2.6/1000 -> 17.008995 | I90: 0 | J90: 0 | K90: 0
A91: NS-EN 10025-2 | B91: S 235 | C91: fuk 360 Mpa | D91: 2 | E91: 8 | F91: 1000 | G91: 8 | H91: =0.3*360*E91^2.6/1000 -> 24.068982 | I91: 0 | J91: 0 | K91: 0
A92: NS-EN 10025-2 | B92: S 235 | C92: fuk 360 Mpa | D92: 2 | E92: 10 | F92: 1000 | G92: 10 | H92: =0.3*360*E92^2.6/1000 -> 42.995574 | I92: 0 | J92: 0 | K92: 0
...

Sheet ESSVE Screws
A1: Produsent | B1: Type | C1: Usage | D1: Highest service class | E1: d | F1: l | G1: dh | H1: My,Rk [Nm] | I1: faxk[N/mm^2] | J1: fhead,k[N/mm^2] | K1: ftens,k[kN] | L1: l1 | M1: l3
A2: ESSVE | B2: CY-FT | C2: Helgjenget, sylindrisk hode, C2 | D2: 2 | E2: 8 | F2: 160 | G2: 10.2 | H2: 20.3 | I2: 13.1 | J2: 0 | K2: 24.1 | L2: 150
A3: ESSVE | B3: CY-FT | C3: Helgjenget, sylindrisk hode, C2 | D3: 2 | E3: 8 | F3: 180 | G3: 10.2 | H3: 20.3 | I3: 13.1 | J3: 0 | K3: 24.1 | L3: 170
A4: ESSVE | B4: CY-FT | C4: Helgjenget, sylindrisk hode, C2 | D4: 2 | E4: 8 | F4: 200 | G4: 10.2 | H4: 20.3 | I4: 13.1 | J4: 0 | K4: 24.1 | L4: 190
A5: ESSVE | B5: CY-FT | C5: Helgjenget, sylindrisk hode, C2 | D5: 2 | E5: 8 | F5: 220 | G5: 10.2 | H5: 20.3 | I5: 13.1 | J5: 0 | K5: 24.1 | L5: 210
A6: ESSVE | B6: CY-FT | C6: Helgjenget, sylindrisk hode, C2 | D6: 2 | E6: 8 | F6: 240 | G6: 10.2 | H6: 20.3 | I6: 13.1 | J6: 0 | K6: 24.1 | L6: 230
A7: ESSVE | B7: CY-FT | C7: Helgjenget, sylindrisk hode, C2 | D7: 2 | E7: 8 | F7: 260 | G7: 10.2 | H7: 20.3 | I7: 13.1 | J7: 0 | K7: 24.1 | L7: 250
A8: ESSVE | B8: CY-FT | C8: Helgjenget, sylindrisk hode, C2 | D8: 2 | E8: 8 | F8: 280 | G8: 10.2 | H8: 20.3 | I8: 13.1 | J8: 0 | K8: 24.1 | L8: 270
A9: ESSVE | B9: CY-FT | C9: Helgjenget, sylindrisk hode, C2 | D9: 2 | E9: 8 | F9: 300 | G9: 10.2 | H9: 20.3 | I9: 13.1 | J9: 0 | K9: 24.1 | L9: 290
A10: ESSVE | B10: CY-FT | C10: Helgjenget, sylindrisk hode, C2 | D10: 2 | E10: 8 | F10: 325 | G10: 10.2 | H10: 20.3 | I10: 13.1 | J10: 0 | K10: 24.1 | L10: 315
A11: ESSVE | B11: CY-FT | C11: Helgjenget, sylindrisk hode, C2 | D11: 2 | E11: 10 | F11: 300 | G11: 13.4 | H11: 36.7 | I11: 12.5 | J11: 0 | K11: 40 | L11: 288
A12: ESSVE | B12: CY-FT | C12: Helgjenget, sylindrisk hode, C2 | D12: 2 | E12: 10 | F12: 325 | G12: 13.4 | H12: 36.7 | I12: 12.5 | J12: 0 | K12: 40 | L12: 301
A13: ESSVE | B13: CY-FT | C13: Helgjenget, sylindrisk hode, C2 | D13: 2 | E13: 10 | F13: 350 | G13: 13.4 | H13: 36.7 | I13: 12.5 | J13: 0 | K13: 40 | L13: 326
... A66: ESSVE | B66: H-FT | C66: Helgjenget, sekskanthode, C1 | D66: 1 | E66: 12 | F66: 220 | G66: 17 | H66: 48.5 | I66: 11.2 | J66: 17.1 | K66: 45 | L66: 205
A67: ESSVE | B67: ET-T | C67: Dobbelgjenget, sylinderhode, C4 | D67: 3 | E67: 6.5 | F67: 65 | G67: 8 | H67: 13 | I67: 15.7 | J67: 0 | K67: 14.8 | L67: 22 | M67: 22
A68: ESSVE | B68: ET-T | C68: Dobbelgjenget, sylinderhode, C4 | D68: 3 | E68: 6.5 | F68: 90 | G68: 8 | H68: 13 | I68: 15.7 | J68: 0 | K68: 14.8 | L68: 38 | M68: 38
A69: ESSVE | B69: ET-T | C69: Dobbelgjenget, sylinderhode, C4 | D69: 3 | E69: 6.5 | F69: 130 | G69: 8 | H69: 13 | I69: 15.7 | J69: 0 | K69: 14.8 | L69: 38 | M69: 38
A70: ESSVE | B70: ET-T | C70: Dobbelgjenget, sylinderhode, C4 | D70: 3 | E70: 6.5 | F70: 160 | G70: 8 | H70: 13 | I70: 15.7 | J70: 0 | K70: 14.8 | L70: 60 | M70: 60
A71: ESSVE | B71: ET-T | C71: Dobbelgjenget, sylinderhode, C4 | D71: 3 | E71: 6.5 | F71: 190 | G71: 8 | H71: 13 | I71: 15.7 | J71: 0 | K71: 14.8 | L71: 80 | M71: 80
A72: ESSVE | B72: ET-T | C72: Dobbelgjenget, sylinderhode, C4 | D72: 3 | E72: 6.5 | F72: 220 | G72: 8 | H72: 13 | I72: 15.7 | J72: 0 | K72: 14.8 | L72: 95 | M72: 95
A73: ESSVE | B73: ET-T | C73: Dobbelgjenget, sylinderhode, C4 | D73: 3 | E73: 8.2 | F73: 90 | G73: 10 | H73: 24.5 | I73: 13.1 | J73: 0 | K73: 23.2 | L73: 38 | M73: 38
A74: ESSVE | B74: ET-T | C74: Dobbelgjenget, sylinderhode, C4 | D74: 3 | E74: 8.2 | F74: 130 | G74: 10 | H74: 24.5 | I74: 13.1 | J74: 0 | K74: 23.2 | L74: 38 | M74: 38
A75: ESSVE | B75: ET-T | C75: Dobbelgjenget, sylinderhode, C4 | D75: 3 | E75: 8.2 | F75: 160 | G75: 10 | H75: 24.5 | I75: 13.1 | J75: 0 | K75: 23.2 | L75: 60 | M75: 60
A76: ESSVE | B76: ET-T | C76: Dobbelgjenget, sylinderhode, C4 | D76: 3 | E76: 8.2 | F76: 190 | G76: 10 | H76: 24.5 | I76: 13.1 | J76: 0 | K76: 23.2 | L76: 80 | M76: 80
A77: ESSVE | B77: ET-T | C77: Dobbelgjenget, sylinderhode, C4 | D77: 3 | E77: 8.2 | F77: 220 | G77: 10 | H77: 24.5 | I77: 13.1 | J77: 0 | K77: 23.2 | L77: 95 | M77: 95
A78: ESSVE | B78: ET-T | C78: Dobbelgjenget, sylinderhode, C4 | D78: 3 | E78: 8.2 | F78: 245 | G78: 10 | H78: 24.5 | I78: 13.1 | J78: 0 | K78: 23.2 | L78: 107 | M78: 107
... A81: ESSVE | B81: ET-T | C81: Dobbelgjenget, sylinderhode, C4 | D81: 3 | E81: 8.2 | F81: 330 | G81: 10 | H81: 24.5 | I81: 13.1 | J81: 0 | K81: 23.2 | L81: 135 | M81: 135
A82: ESSVE | B82: HEX | C82: Sekskanthode, C1 | D82: 3 | E82: 6 | F82: 50 | G82: 12.5 | H82: 9.9 | I82: 9.2 | J82: 14.9 | K82: 9.5 | L82: 40
A83: ESSVE | B83: HEX | C83: Sekskanthode, C2 | D83: 3 | E83: 6 | F83: 70 | G83: 12.5 | H83: 9.9 | I83: 9.2 | J83: 14.9 | K83: 9.5 | L83: 40
A84: ESSVE | B84: HEX | C84: Sekskanthode, C3 | D84: 3 | E84: 6 | F84: 90 | G84: 12.5 | H84: 9.9 | I84: 9.2 | J84: 14.9 | K84: 9.5 | L84: 50
A85: ESSVE | B85: HEX | C85: Sekskanthode, C4 | D85: 3 | E85: 6 | F85: 120 | G85: 12.5 | H85: 9.9 | I85: 9.2 | J85: 14.9 | K85: 9.5 | L85: 75
A86: ESSVE | B86: HEX | C86: Sekskanthode, C4 | D86: 3 | E86: 6 | F86: 140 | G86: 12.5 | H86: 9.9 | I86: 9.2 | J86: 14.9 | K86: 9.5 | L86: 75
A87: ESSVE | B87: HEX | C87: Sekskanthode, C4 | D87: 3 | E87: 8 | F87: 70 | G87: 15 | H87: 21.7 | I87: 10.6 | J87: 10.8 | K87: 19 | L87: 50
A88: ESSVE | B88: HEX | C88: Sekskanthode, C4 | D88: 3 | E88: 8 | F88: 90 | G88: 15 | H88: 21.7 | I88: 10.6 | J88: 10.8 | K88: 19 | L88: 50
A89: ESSVE | B89: HEX | C89: Sekskanthode, C4 | D89: 3 | E89: 8 | F89: 120 | G89: 15 | H89: 21.7 | I89: 10.6 | J89: 10.8 | K89: 19 | L89: 50
A90: ESSVE | B90: HEX | C90: Sekskanthode, C4 | D90: 3 | E90: 8 | F90: 160 | G90: 15 | H90: 21.7 | I90: 10.6 | J90: 10.8 | K90: 19 | L90: 50
A91: ESSVE | B91: HEX | C91: Sekskanthode, C4 | D91: 3 | E91: 8 | F91: 200 | G91: 15 | H91: 21.7 | I91: 10.6 | J91: 10.8 | K91: 19 | L91: 50
A92: ESSVE | B92: HEX | C92: Sekskanthode, C4 | D92: 3 | E92: 8 | F92: 240 | G92: 15 | H92: 21.7 | I92: 10.6 | J92: 10.8 | K92: 19 | L92: 50
A93: ESSVE | B93: HEX | C93: Sekskanthode, C4 | D93: 3 | E93: 10 | F93: 80 | G93: 18 | H93: 33.5 | I93: 9.1 | J93: 13.7 | K93: 25 | L93: 60
... A180: ESSVE | B180: ESSDRIVE PH FZB | C180: Panhode | D180: 2 | E180: 6 | F180: 100 | G180: 12 | H180: 8.5 | I180: 15.6 | J180: 27.1 | K180: 11.5 | L180: 52
...

Sheet Eurotec Screws
A1: Producer | B1: Product | C1: Detailinformation | D1: Highest service class | E1: d | F1: l | G1: dh | H1: My,Rk [Nm] | I1: faxk[N/mm^2] | J1: fhead,k[N/mm^2] | K1: ftens,k[kN] | L1: l1 | M1: l3 | N1: f_uk | O1: Bmax
A2: EUROTEC | B2: KonstruX ST ZK | C2: Fully threaded screw, Cylinder head, galvanized | D2: 2 | E2: 5.2 | F2: 80 | G2: 6.4 | H2: 10 | I2: 15.5 | J2: 12 | K2: 13 | L2: =F2-5.5 -> 74.5
A3: EUROTEC | B3: KonstruX ST ZK | C3: Fully threaded screw, Cylinder head, galvanized | D3: 2 | E3: 5.2 | F3: 100 | G3: 6.4 | H3: 10 | I3: 15.5 | J3: 12 | K3: 13 | L3: =F3-5.5 -> 94.5
A4: EUROTEC | B4: KonstruX ST ZK | C4: Fully threaded screw, Cylinder head, galvanized | D4: 2 | E4: 5.2 | F4: 120 | G4: 6.4 | H4: 10 | I4: 15.5 | J4: 12 | K4: 13 | L4: =F4-5.5 -> 114.5
A5: EUROTEC | B5: KonstruX ST ZK | C5: Fully threaded screw, Cylinder head, galvanized | D5: 2 | E5: 5.2 | F5: 140 | G5: 6.4 | H5: 10 | I5: 15.5 | J5: 12 | K5: 13 | L5: =F5-5.5 -> 134.5
A6: EUROTEC | B6: KonstruX ST ZK | C6: Fully threaded screw, Cylinder head, galvanized | D6: 2 | E6: 5.2 | F6: 160 | G6: 6.4 | H6: 10 | I6: 15.5 | J6: 12 | K6: 13 | L6: =F6-5.5 -> 154.5
A7: EUROTEC | B7: KonstruX ST ZK | C7: Fully threaded screw, Cylinder head, galvanized | D7: 2 | E7: 5.9 | F7: 80 | G7: 8 | H7: 10 | I7: 15.5 | J7: 12 | K7: 17 | L7: =F7-5.5 -> 74.5
A8: EUROTEC | B8: KonstruX ST ZK | C8: Fully threaded screw, Cylinder head, galvanized | D8: 2 | E8: 5.9 | F8: 100 | G8: 8 | H8: 15 | I8: 15.5 | J8: 12 | K8: 17 | L8: =F8-5.5 -> 94.5
A9: EUROTEC | B9: KonstruX ST ZK | C9: Fully threaded screw, Cylinder head, galvanized | D9: 2 | E9: 5.9 | F9: 120 | G9: 8 | H9: 15 | I9: 15.5 | J9: 12 | K9: 17 | L9: =F9-5.5 -> 114.5
A10: EUROTEC | B10: KonstruX ST ZK | C10: Fully threaded screw, Cylinder head, galvanized | D10: 2 | E10: 5.9 | F10: 140 | G10: 8 | H10: 15 | I10: 15.5 | J10: 12 | K10: 17 | L10: =F10-5.5 -> 134.5
A11: EUROTEC | B11: KonstruX ST ZK | C11: Fully threaded screw, Cylinder head, galvanized | D11: 2 | E11: 5.9 | F11: 160 | G11: 8 | H11: 15 | I11: 15.5 | J11: 12 | K11: 17 | L11: =F11-5.5 -> 154.5
A12: EUROTEC | B12: KonstruX ST ZK | C12: Fully threaded screw, Cylinder head, galvanized | D12: 2 | E12: 5.9 | F12: 180 | G12: 8 | H12: 15 | I12: 15.5 | J12: 12 | K12: 17 | L12: =F12-5.5 -> 174.5
A13: EUROTEC | B13: KonstruX ST ZK | C13: Fully threaded screw, Cylinder head, galvanized | D13: 2 | E13: 5.9 | F13: 200 | G13: 8 | H13: 15 | I13: 15.5 | J13: 12 | K13: 17 | L13: =F13-5.5 -> 194.5
... A23: EUROTEC | B23: KonstruX ST ZK | C23: Fully threaded screw, Cylinder head, galvanized | D23: 2 | E23: 6.5 | F23: 260 | G23: 8 | H23: 15 | I23: 11.4 | J23: 12 | K23: 17 | L23: =F23-5.5 -> 254.5
A24: EUROTEC | B24: KonstruX ST ZK | C24: Fully threaded screw, Cylinder head, galvanized | D24: 2 | E24: 8 | F24: 155 | G24: 10 | H24: 25 | I24: 11.1 | J24: 12 | K24: 25 | L24: =F24-6.5 -> 148.5
A25: EUROTEC | B25: KonstruX ST ZK | C25: Fully threaded screw, Cylinder head, galvanized | D25: 2 | E25: 8 | F25: 195 | G25: 10 | H25: 25 | I25: 11.1 | J25: 12 | K25: 25 | L25: =F25-6.5 -> 188.5
A26: EUROTEC | B26: KonstruX ST ZK | C26: Fully threaded screw, Cylinder head, galvanized | D26: 2 | E26: 8 | F26: 220 | G26: 10 | H26: 25 | I26: 11.1 | J26: 12 | K26: 25 | L26: =F26-6.5 -> 213.5
A27: EUROTEC | B27: KonstruX ST ZK | C27: Fully threaded screw, Cylinder head, galvanized | D27: 2 | E27: 8 | F27: 245 | G27: 10 | H27: 25 | I27: 11.1 | J27: 12 | K27: 25 | L27: =F27-6.5 -> 238.5
A28: EUROTEC | B28: KonstruX ST ZK | C28: Fully threaded screw, Cylinder head, galvanized | D28: 2 | E28: 8 | F28: 295 | G28: 10 | H28: 25 | I28: 11.1 | J28: 12 | K28: 25 | L28: =F28-6.5 -> 288.5
A29: EUROTEC | B29: KonstruX ST ZK | C29: Fully threaded screw, Cylinder head, galvanized | D29: 2 | E29: 8 | F29: 330 | G29: 10 | H29: 25 | I29: 11.1 | J29: 12 | K29: 25 | L29: =F29-6.5 -> 323.5
A30: EUROTEC | B30: KonstruX ST ZK | C30: Fully threaded screw, Cylinder head, galvanized | D30: 2 | E30: 8 | F30: 375 | G30: 10 | H30: 25 | I30: 11.1 | J30: 12 | K30: 25 | L30: =F30-6.5 -> 368.5
A31: EUROTEC | B31: KonstruX ST ZK | C31: Fully threaded screw, Cylinder head, galvanized | D31: 2 | E31: 8 | F31: 400 | G31: 10 | H31: 25 | I31: 11.1 | J31: 12 | K31: 25 | L31: =F31-6.5 -> 393.5
A32: EUROTEC | B32: KonstruX ST ZK | C32: Fully threaded screw, Cylinder head, galvanized | D32: 2 | E32: 8 | F32: 430 | G32: 10 | H32: 25 | I32: 11.1 | J32: 12 | K32: 25 | L32: =F32-6.5 -> 423.5
A33: EUROTEC | B33: KonstruX ST ZK | C33: Fully threaded screw, Cylinder head, galvanized | D33: 2 | E33: 8 | F33: 480 | G33: 10 | H33: 25 | I33: 11.1 | J33: 12 | K33: 25 | L33: =F33-6.5 -> 473.5
A34: EUROTEC | B34: KonstruX ST ZK | C34: Fully threaded screw, Cylinder head, galvanized | D34: 2 | E34: 8 | F34: 530 | G34: 10 | H34: 25 | I34: 11.1 | J34: 12 | K34: 25 | L34: =F34-6.5 -> 523.5
A35: EUROTEC | B35: KonstruX ST ZK | C35: Fully threaded screw, Cylinder head, galvanized | D35: 2 | E35: 8 | F35: 580 | G35: 10 | H35: 25 | I35: 11.1 | J35: 12 | K35: 25 | L35: =F35-6.5 -> 573.5
... A53: EUROTEC | B53: KonstruX ST ZK | C53: Fully threaded screw, Cylinder head, galvanized | D53: 2 | E53: 10 | F53: 1000 | G53: 13 | H53: 40 | I53: 10.8 | J53: 12 | K53: 33 | L53: =F53-6.5 -> 993.5
A54: EUROTEC | B54: KonstruX ST SK | C54: Fully threaded screw, Countersunk head, galvanized | D54: 2 | E54: 5.2 | F54: 80 | G54: 6.4 | H54: 10 | I54: 15.5 | J54: 12 | K54: 13 | L54: =F54-5.5 -> 74.5
A55: EUROTEC | B55: KonstruX ST SK | C55: Fully threaded screw, Countersunk head, galvanized | D55: 2 | E55: 5.2 | F55: 100 | G55: 6.4 | H55: 10 | I55: 15.5 | J55: 12 | K55: 13 | L55: =F55-5.5 -> 94.5
A56: EUROTEC | B56: KonstruX ST SK | C56: Fully threaded screw, Countersunk head, galvanized | D56: 2 | E56: 5.2 | F56: 120 | G56: 6.4 | H56: 10 | I56: 15.5 | J56: 12 | K56: 13 | L56: =F56-5.5 -> 114.5
A57: EUROTEC | B57: KonstruX ST SK | C57: Fully threaded screw, Countersunk head, galvanized | D57: 2 | E57: 5.2 | F57: 140 | G57: 6.4 | H57: 10 | I57: 15.5 | J57: 12 | K57: 13 | L57: =F57-5.5 -> 134.5
A58: EUROTEC | B58: KonstruX ST SK | C58: Fully threaded screw, Countersunk head, galvanized | D58: 2 | E58: 5.2 | F58: 160 | G58: 6.4 | H58: 10 | I58: 15.5 | J58: 12 | K58: 13 | L58: =F58-5.5 -> 154.5
A59: EUROTEC | B59: KonstruX ST SK | C59: Fully threaded screw, Countersunk head, galvanized | D59: 2 | E59: 6.5 | F59: 80 | G59: 11.5 | H59: 15 | I59: 15.5 | J59: 12 | K59: 17 | L59: =F59-5.5 -> 74.5
A60: EUROTEC | B60: KonstruX ST SK | C60: Fully threaded screw, Countersunk head, galvanized | D60: 2 | E60: 6.5 | F60: 100 | G60: 11.5 | H60: 15 | I60: 15.5 | J60: 12 | K60: 17 | L60: =F60-5.5 -> 94.5
A61: EUROTEC | B61: KonstruX ST SK | C61: Fully threaded screw, Countersunk head, galvanized | D61: 2 | E61: 6.5 | F61: 120 | G61: 11.5 | H61: 15 | I61: 15.5 | J61: 12 | K61: 17 | L61: =F61-5.5 -> 114.5
A62: EUROTEC | B62: KonstruX ST SK | C62: Fully threaded screw, Countersunk head, galvanized | D62: 2 | E62: 6.5 | F62: 140 | G62: 11.5 | H62: 15 | I62: 15.5 | J62: 12 | K62: 17 | L62: =F62-5.5 -> 134.5
A63: EUROTEC | B63: KonstruX ST SK | C63: Fully threaded screw, Countersunk head, galvanized | D63: 2 | E63: 8 | F63: 95 | G63: 14.5 | H63: 25 | I63: 12.5 | J63: 12 | K63: 25 | L63: =F63-7.4 -> 87.6
A64: EUROTEC | B64: KonstruX ST SK | C64: Fully threaded screw, Countersunk head, galvanized | D64: 2 | E64: 8 | F64: 125 | G64: 14.5 | H64: 25 | I64: 12.5 | J64: 12 | K64: 25 | L64: =F64-7.4 -> 117.6
A65: EUROTEC | B65: KonstruX ST SK | C65: Fully threaded screw, Countersunk head, galvanized | D65: 2 | E65: 8 | F65: 155 | G65: 14.5 | H65: 25 | I65: 12.5 | J65: 12 | K65: 25 | L65: =F65-7.4 -> 147.6
A66: EUROTEC | B66: KonstruX ST SK | C66: Fully threaded screw, Countersunk head, galvanized | D66: 2 | E66: 8 | F66: 195 | G66: 14.5 | H66: 25 | I66: 12.5 | J66: 12 | K66: 25 | L66: =F66-7.4 -> 187.6
...

Sheet ISO 4014 Bolts
A1: Produsent | B1: Type | C1: Usage | D1: Highest service class | E1: d | F1: l | G1: dh | H1: My,Rk [Nm] | I1: faxk[N/mm^2] | J1: fhead,k[N/mm^2] | K1: ftens,k[kN] | L1: l1 | M1: l3
A2: ISO 4014 | B2: ISO 4014 / DIN 931 | C2: Hexagon Head Bolt | D2: 3 | E2: 6 | F2: 30 | G2: 10 | L2: 18
A3: ISO 4014 | B3: ISO 4014 / DIN 931 | C3: Hexagon Head Bolt | D3: 3 | E3: 6 | F3: 35 | G3: 10 | L3: 18
A4: ISO 4014 | B4: ISO 4014 / DIN 931 | C4: Hexagon Head Bolt | D4: 3 | E4: 6 | F4: 40 | G4: 10 | L4: 18
A5: ISO 4014 | B5: ISO 4014 / DIN 931 | C5: Hexagon Head Bolt | D5: 3 | E5: 6 | F5: 45 | G5: 10 | L5: 18
A6: ISO 4014 | B6: ISO 4014 / DIN 931 | C6: Hexagon Head Bolt | D6: 3 | E6: 6 | F6: 50 | G6: 10 | L6: 18
A7: ISO 4014 | B7: ISO 4014 / DIN 931 | C7: Hexagon Head Bolt | D7: 3 | E7: 6 | F7: 55 | G7: 10 | L7: 18
A8: ISO 4014 | B8: ISO 4014 / DIN 931 | C8: Hexagon Head Bolt | D8: 3 | E8: 6 | F8: 60 | G8: 10 | L8: 18
A9: ISO 4014 | B9: ISO 4014 / DIN 931 | C9: Hexagon Head Bolt | D9: 3 | E9: 6 | F9: 65 | G9: 10 | L9: 18
A10: ISO 4014 | B10: ISO 4014 / DIN 931 | C10: Hexagon Head Bolt | D10: 3 | E10: 6 | F10: 70 | G10: 10 | L10: 18
A11: ISO 4014 | B11: ISO 4014 / DIN 931 | C11: Hexagon Head Bolt | D11: 3 | E11: 6 | F11: 75 | G11: 10 | L11: 18
A12: ISO 4014 | B12: ISO 4014 / DIN 931 | C12: Hexagon Head Bolt | D12: 3 | E12: 6 | F12: 80 | G12: 10 | L12: 18
A13: ISO 4014 | B13: ISO 4014 / DIN 931 | C13: Hexagon Head Bolt | D13: 3 | E13: 6 | F13: 85 | G13: 10 | L13: 18
... A414: ISO 4014 | B414: ISO 4014 / DIN 931 | C414: Hexagon Head Bolt | D414: 3 | E414: 39 | F414: 280 | G414: 60 | L414: 103
Y633: 100
Y634: 100
Y635: 100
Y636: 100
Y637: 100
Y638: 100
Y639: 50
Y640: 50
Y641: 50
Y642: 50
Y643: 50
Y644: 50
... Y665: 25

Sheet Motek screws
A1: Produsent | B1: Type | C1: Usage | D1: Highest service class | E1: d | F1: l | G1: dh | H1: My,Rk [Nm] | I1: faxk[N/mm^2] | J1: fhead,k[N/mm^2] | K1: ftens,k[kN] | L1: l1 | M1: l3
A2: MOTEK | B2: Treskrue bygg | C2: Varmforsinket, 8.8, C3 | D2: 3 | E2: 6 | F2: 40 | G2: 14.2 | H2: 11.956 | I2: 16.56 | J2: 28.76 | K2: 10.71 | L2: 40
A3: MOTEK | B3: Treskrue bygg | C3: Varmforsinket, 8.8, C3 | D3: 3 | E3: 6 | F3: 45 | G3: 14.2 | H3: 11.956 | I3: 16.56 | J3: 28.76 | K3: 10.71 | L3: 45
A4: MOTEK | B4: Treskrue bygg | C4: Varmforsinket, 8.8, C3 | D4: 3 | E4: 6 | F4: 50 | G4: 14.2 | H4: 11.956 | I4: 16.56 | J4: 28.76 | K4: 10.71 | L4: 50
A5: MOTEK | B5: Treskrue bygg | C5: Varmforsinket, 8.8, C3 | D5: 3 | E5: 6 | F5: 60 | G5: 14.2 | H5: 11.956 | I5: 16.56 | J5: 28.76 | K5: 10.71 | L5: 60
A6: MOTEK | B6: Treskrue bygg | C6: Varmforsinket, 8.8, C3 | D6: 3 | E6: 6 | F6: 70 | G6: 14.2 | H6: 11.956 | I6: 16.56 | J6: 28.76 | K6: 10.71 | L6: 70
A7: MOTEK | B7: Treskrue bygg | C7: Varmforsinket, 8.8, C3 | D7: 3 | E7: 6 | F7: 80 | G7: 14.2 | H7: 11.956 | I7: 16.56 | J7: 28.76 | K7: 10.71 | L7: 80
A8: MOTEK | B8: Treskrue bygg | C8: Varmforsinket, 8.8, C3 | D8: 3 | E8: 6 | F8: 90 | G8: 14.2 | H8: 11.956 | I8: 16.56 | J8: 28.76 | K8: 10.71 | L8: 90
A9: MOTEK | B9: Treskrue bygg | C9: Varmforsinket, 8.8, C3 | D9: 3 | E9: 6 | F9: 100 | G9: 14.2 | H9: 11.956 | I9: 16.56 | J9: 28.76 | K9: 10.71 | L9: 100
A10: MOTEK | B10: Treskrue bygg | C10: Varmforsinket, 8.8, C3 | D10: 3 | E10: 8 | F10: 40 | G10: 18 | H10: 28.808 | I10: 15.14 | J10: 24.13 | K10: 19.58 | L10: 40
A11: MOTEK | B11: Treskrue bygg | C11: Varmforsinket, 8.8, C3 | D11: 3 | E11: 8 | F11: 50 | G11: 18 | H11: 28.808 | I11: 15.14 | J11: 24.13 | K11: 19.58 | L11: 50
A12: MOTEK | B12: Treskrue bygg | C12: Varmforsinket, 8.8, C3 | D12: 3 | E12: 8 | F12: 60 | G12: 18 | H12: 28.808 | I12: 15.14 | J12: 24.13 | K12: 19.58 | L12: 60
A13: MOTEK | B13: Treskrue bygg | C13: Varmforsinket, 8.8, C3 | D13: 3 | E13: 8 | F13: 70 | G13: 18 | H13: 28.808 | I13: 15.14 | J13: 24.13 | K13: 19.58 | L13: 70
... A35: MOTEK | B35: Treskrue montasje | C35: Settherdet kullstål C1022, C4 | D35: 3 | E35: 6 | F35: 50 | G35: 13.5 | H35: 12.35 | I35: 17.32 | J35: 27.19 | K35: 14.01 | L35: 43
A36: MOTEK | B36: Treskrue montasje | C36: Settherdet kullstål C1022, C4 | D36: 3 | E36: 6 | F36: 60 | G36: 13.5 | H36: 12.35 | I36: 17.32 | J36: 27.19 | K36: 14.01 | L36: 30 | M36: 5
A37: MOTEK | B37: Treskrue montasje | C37: Settherdet kullstål C1022, C4 | D37: 3 | E37: 6 | F37: 70 | G37: 13.5 | H37: 12.35 | I37: 17.32 | J37: 27.19 | K37: 14.01 | L37: 42 | M37: 10.2
A38: MOTEK | B38: Treskrue montasje | C38: Settherdet kullstål C1022, C4 | D38: 3 | E38: 6 | F38: 80 | G38: 13.5 | H38: 12.35 | I38: 17.32 | J38: 27.19 | K38: 14.01 | L38: 48 | M38: 10.2
A39: MOTEK | B39: Treskrue montasje | C39: Settherdet kullstål C1022, C4 | D39: 3 | E39: 6 | F39: 90 | G39: 13.5 | H39: 12.35 | I39: 17.32 | J39: 27.19 | K39: 14.01 | L39: 55 | M39: 10.2
A40: MOTEK | B40: Treskrue montasje | C40: Settherdet kullstål C1022, C4 | D40: 3 | E40: 6 | F40: 100 | G40: 13.5 | H40: 12.35 | I40: 17.32 | J40: 27.19 | K40: 14.01 | L40: 60 | M40: 10.2
A41: MOTEK | B41: Treskrue montasje | C41: Settherdet kullstål C1022, C4 | D41: 3 | E41: 6 | F41: 120 | G41: 13.5 | H41: 12.35 | I41: 17.32 | J41: 27.19 | K41: 14.01 | L41: 60 | M41: 10.2
A42: MOTEK | B42: Treskrue montasje | C42: Settherdet kullstål C1022, C4 | D42: 3 | E42: 6 | F42: 140 | G42: 13.5 | H42: 12.35 | I42: 17.32 | J42: 27.19 | K42: 14.01 | L42: 70 | M42: 10.2
A43: MOTEK | B43: Treskrue montasje | C43: Settherdet kullstål C1022, C4 | D43: 3 | E43: 8 | F43: 50 | G43: 20.5 | H43: 24.789 | I43: 15.7 | J43: 23.7 | K43: 24.85 | L43: 50
A44: MOTEK | B44: Treskrue montasje | C44: Settherdet kullstål C1022, C4 | D44: 3 | E44: 8 | F44: 60 | G44: 20.5 | H44: 24.789 | I44: 15.7 | J44: 23.7 | K44: 24.85 | L44: 60
A45: MOTEK | B45: Treskrue montasje | C45: Settherdet kullstål C1022, C4 | D45: 3 | E45: 8 | F45: 70 | G45: 20.5 | H45: 24.789 | I45: 15.7 | J45: 23.7 | K45: 24.85 | L45: 70
A46: MOTEK | B46: Treskrue montasje | C46: Settherdet kullstål C1022, C4 | D46: 3 | E46: 8 | F46: 80 | G46: 20.5 | H46: 24.789 | I46: 15.7 | J46: 23.7 | K46: 24.85 | L46: 42 | M46: 10.2
A47: MOTEK | B47: Treskrue montasje | C47: Settherdet kullstål C1022, C4 | D47: 3 | E47: 8 | F47: 100 | G47: 20.5 | H47: 24.789 | I47: 15.7 | J47: 23.7 | K47: 24.85 | L47: 55 | M47: 10.2
A48: MOTEK | B48: Treskrue montasje | C48: Settherdet kullstål C1022, C4 | D48: 3 | E48: 8 | F48: 120 | G48: 20.5 | H48: 24.789 | I48: 15.7 | J48: 23.7 | K48: 24.85 | L48: 70 | M48: 10.2
A49: MOTEK | B49: Treskrue montasje | C49: Settherdet kullstål C1022, C4 | D49: 3 | E49: 8 | F49: 140 | G49: 20.5 | H49: 24.789 | I49: 15.7 | J49: 23.7 | K49: 24.85 | L49: 70 | M49: 10.2
A50: MOTEK | B50: Treskrue montasje | C50: Settherdet kullstål C1022, C4 | D50: 3 | E50: 8 | F50: 160 | G50: 20.5 | H50: 24.789 | I50: 15.7 | J50: 23.7 | K50: 24.85 | L50: 70 | M50: 10.2
A51: MOTEK | B51: Treskrue montasje | C51: Settherdet kullstål C1022, C4 | D51: 3 | E51: 8 | F51: 180 | G51: 20.5 | H51: 24.789 | I51: 15.7 | J51: 23.7 | K51: 24.85 | L51: 70 | M51: 10.2
A52: MOTEK | B52: Treskrue montasje | C52: Settherdet kullstål C1022, C4 | D52: 3 | E52: 8 | F52: 200 | G52: 20.5 | H52: 24.789 | I52: 15.7 | J52: 23.7 | K52: 24.85 | L52: 70 | M52: 10.2
A53: MOTEK | B53: Treskrue montasje | C53: Settherdet kullstål C1022, C4 | D53: 3 | E53: 8 | F53: 220 | G53: 20.5 | H53: 24.789 | I53: 15.7 | J53: 23.7 | K53: 24.85 | L53: 70 | M53: 10.2
A54: MOTEK | B54: Treskrue montasje | C54: Settherdet kullstål C1022, C4 | D54: 3 | E54: 8 | F54: 260 | G54: 20.5 | H54: 24.789 | I54: 15.7 | J54: 23.7 | K54: 24.85 | L54: 70 | M54: 10.2
A55: MOTEK | B55: Treskrue montasje | C55: Settherdet kullstål C1022, C4 | D55: 3 | E55: 8 | F55: 300 | G55: 20.5 | H55: 24.789 | I55: 15.7 | J55: 23.7 | K55: 24.85 | L55: 70 | M55: 10.2
A56: MOTEK | B56: Treskrue montasje | C56: Settherdet kullstål C1022, C4 | D56: 3 | E56: 8 | F56: 340 | G56: 20.5 | H56: 24.789 | I56: 15.7 | J56: 23.7 | K56: 24.85 | L56: 70 | M56: 10.2
Y243: 100
Y244: 100
Y245: 100
Y246: 100
Y247: 100
...

Sheet Rothoblaas Nails
A1: Produsent | B1: Type | C1: Usage | D1: Highest service class | E1: d | F1: l | G1: dh | H1: My,Rk [Nm] | I1: faxk[N/mm^2] | J1: fhead,k[N/mm^2] | K1: ftens,k[kN] | N1: Nettside | O1: Ah | P1: ht
A2: ROTHOBLAAS | B2: LBA | C2: High Bond Nail | D2: 2 | E2: 4 | F2: 40 | G2: 8 | H2: 6.68 | I2: 6.43 | K2: 6.5
A3: ROTHOBLAAS | B3: LBA | C3: High Bond Nail | D3: 2 | E3: 4 | F3: 50 | G3: 8 | H3: 6.68 | I3: 6.43 | K3: 6.5
A4: ROTHOBLAAS | B4: LBA | C4: High Bond Nail | D4: 2 | E4: 4 | F4: 60 | G4: 8 | H4: 6.68 | I4: 6.43 | K4: 6.5
A5: ROTHOBLAAS | B5: LBA | C5: High Bond Nail | D5: 2 | E5: 4 | F5: 75 | G5: 8 | H5: 6.68 | I5: 6.43 | K5: 6.5
A6: ROTHOBLAAS | B6: LBA | C6: High Bond Nail | D6: 2 | E6: 4 | F6: 100 | G6: 8 | H6: 6.68 | I6: 6.43 | K6: 6.5
A7: ROTHOBLAAS | B7: LBA | C7: High Bond Nail | D7: 2 | E7: 6 | F7: 60 | G7: 12 | H7: 20.2 | I7: 6.43 | K7: 17
A8: ROTHOBLAAS | B8: LBA | C8: High Bond Nail | D8: 2 | E8: 6 | F8: 80 | G8: 12 | H8: 20.2 | I8: 6.43 | K8: 17
A9: ROTHOBLAAS | B9: LBA | C9: High Bond Nail | D9: 2 | E9: 6 | F9: 100 | G9: 12 | H9: 20.2 | I9: 6.43 | K9: 17
A10: ROTHOBLAAS | B10: LBAI | C10: High Bond Nail | D10: 3 | E10: 4 | F10: 50 | G10: 8 | H10: 7.18 | I10: 6.43 | K10: 6.5

Sheet Rothoblaas Screws
A1: Produsent | B1: Type | C1: Usage | D1: Highest service class | E1: d | F1: l | G1: dh | H1: My,Rk [Nm] | I1: faxk[N/mm^2] | J1: fhead,k[N/mm^2] | K1: ftens,k[kN] | L1: l1 | M1: l3
A2: ROTHOBLAAS | B2: CTC | C2: Timber-to-concrete floors | D2: 2 | E2: 9 | F2: 240 | G2: 11.5 | H2: 38 | I2: 11.3 | K2: 30 | L2: 190
A3: ROTHOBLAAS | B3: CTC | C3: Timber-to-concrete floors | D3: 2 | E3: 9 | F3: 160 | G3: 11.5 | H3: 38 | I3: 11.3 | K3: 30 | L3: 110
A4: ROTHOBLAAS | B4: CTC | C4: Timber-to-concrete floors | D4: 2 | E4: 7 | F4: 240 | G4: 9.5 | H4: 20 | I4: 11.3 | K4: 20 | L4: 190
A5: ROTHOBLAAS | B5: CTC | C5: Timber-to-concrete floors | D5: 2 | E5: 7 | F5: 160 | G5: 9.5 | H5: 20 | I5: 11.3 | K5: 20 | L5: 110
A6: ROTHOBLAAS | B6: HBSPLATE | C6: Pan Head Screw | D6: 2 | E6: 8 | F6: 80 | G6: 13.5 | H6: 33.4 | I6: 11.7 | J6: 10.5 | K6: 11.3 | L6: 55
A7: ROTHOBLAAS | B7: HBSPLATE | C7: Pan Head Screw | D7: 2 | E7: 8 | F7: 100 | G7: 13.5 | H7: 33.4 | I7: 11.7 | J7: 10.5 | K7: 11.3 | L7: 75
A8: ROTHOBLAAS | B8: HBSPLATE | C8: Pan Head Screw | D8: 2 | E8: 8 | F8: 120 | G8: 13.5 | H8: 33.4 | I8: 11.7 | J8: 10.5 | K8: 11.3 | L8: 95
A9: ROTHOBLAAS | B9: HBSPLATE | C9: Pan Head Screw | D9: 2 | E9: 8 | F9: 140 | G9: 13.5 | H9: 33.4 | I9: 11.7 | J9: 10.5 | K9: 11.3 | L9: 110
A10: ROTHOBLAAS | B10: HBSPLATE | C10: Pan Head Screw | D10: 2 | E10: 8 | F10: 160 | G10: 13.5 | H10: 33.4 | I10: 11.7 | J10: 10.5 | K10: 11.3 | L10: 130
A11: ROTHOBLAAS | B11: HBSPLATE | C11: Pan Head Screw | D11: 2 | E11: 10 | F11: 100 | G11: 16.5 | H11: 45 | I11: 11.7 | J11: 10.5 | K11: 20.1 | L11: 75
A12: ROTHOBLAAS | B12: HBSPLATE | C12: Pan Head Screw | D12: 2 | E12: 10 | F12: 120 | G12: 16.5 | H12: 45 | I12: 11.7 | J12: 10.5 | K12: 20.1 | L12: 95
A13: ROTHOBLAAS | B13: HBSPLATE | C13: Pan Head Screw | D13: 2 | E13: 10 | F13: 140 | G13: 16.5 | H13: 45 | I13: 11.7 | J13: 10.5 | K13: 20.1 | L13: 110
A14: ROTHOBLAAS | B14: HBSPLATE | C14: Pan Head Screw | D14: 2 | E14: 10 | F14: 160 | G14: 16.5 | H14: 45 | I14: 11.7 | J14: 10.5 | K14: 20.1 | L14: 130
A15: ROTHOBLAAS | B15: HBSPLATE | C15: Pan Head Screw | D15: 2 | E15: 10 | F15: 180 | G15: 16.5 | H15: 45 | I15: 11.7 | J15: 10.5 | K15: 20.1 | L15: 150
A16: ROTHOBLAAS | B16: HBSPLATE | C16: Pan Head Screw | D16: 2 | E16: 12 | F16: 120 | G16: 18.5 | H16: 65 | I16: 11.7 | J16: 10.5 | K16: 31.4 | L16: 90
A17: ROTHOBLAAS | B17: HBSPLATE | C17: Pan Head Screw | D17: 2 | E17: 12 | F17: 140 | G17: 18.5 | H17: 65 | I17: 11.7 | J17: 10.5 | K17: 31.4 | L17: 110
... A155: ROTHOBLAAS | B155: HBSEVO | C155: Countersunk screw | D155: 3 | E155: 5 | F155: 80 | G155: 10 | H155: 5.4 | I155: 11.7 | J155: 10.5 | K155: 7.9 | L155: 45
A156: ROTHOBLAAS | B156: LBS | C156: Round head screw for plates | D156: 2 | E156: 7 | F156: 100 | G156: 11 | H156: 14.2 | I156: 11.7 | J156: 10.5 | K156: 15.4 | L156: =F156 -> 100
A157: ROTHOBLAAS | B157: LBS | C157: Round head screw for plates | D157: 2 | E157: 7 | F157: 80 | G157: 11 | H157: 14.2 | I157: 11.7 | J157: 10.5 | K157: 15.4 | L157: =F157 -> 80
A158: ROTHOBLAAS | B158: LBS | C158: Round head screw for plates | D158: 2 | E158: 7 | F158: 60 | G158: 11 | H158: 14.2 | I158: 11.7 | J158: 10.5 | K158: 15.4 | L158: =F158 -> 60
A159: ROTHOBLAAS | B159: LBS | C159: Round head screw for plates | D159: 2 | E159: 5 | F159: 70 | G159: 7.8 | H159: 5.4 | I159: 11.7 | J159: 10.5 | K159: 7.9 | L159: =F159 -> 70
A160: ROTHOBLAAS | B160: LBS | C160: Round head screw for plates | D160: 2 | E160: 5 | F160: 60 | G160: 7.8 | H160: 5.4 | I160: 11.7 | J160: 10.5 | K160: 7.9 | L160: =F160 -> 60
A161: ROTHOBLAAS | B161: LBS | C161: Round head screw for plates | D161: 2 | E161: 5 | F161: 50 | G161: 7.8 | H161: 5.4 | I161: 11.7 | J161: 10.5 | K161: 7.9 | L161: =F161 -> 50
A162: ROTHOBLAAS | B162: LBS | C162: Round head screw for plates | D162: 2 | E162: 5 | F162: 40 | G162: 7.8 | H162: 5.4 | I162: 11.7 | J162: 10.5 | K162: 7.9 | L162: =F162 -> 40
A163: ROTHOBLAAS | B163: LBS | C163: Round head screw for plates | D163: 2 | E163: 5 | F163: 25 | G163: 7.8 | H163: 5.4 | I163: 11.7 | J163: 10.5 | K163: 7.9 | L163: =F163 -> 25
A164: ROTHOBLAAS | B164: SKR | C164: Concrete screw hexagonal | D164: 2 | E164: 12 | F164: 400 | G164: 18 | L164: 100
A165: ROTHOBLAAS | B165: SKR | C165: Concrete screw hexagonal | D165: 2 | E165: 12 | F165: 320 | G165: 18 | L165: 100
A166: ROTHOBLAAS | B166: SKR | C166: Concrete screw hexagonal | D166: 2 | E166: 12 | F166: 280 | G166: 18 | L166: 100
A167: ROTHOBLAAS | B167: SKR | C167: Concrete screw hexagonal | D167: 2 | E167: 12 | F167: 240 | G167: 18 | L167: 100
A168: ROTHOBLAAS | B168: SKR | C168: Concrete screw hexagonal | D168: 2 | E168: 12 | F168: 200 | G168: 18 | L168: 100
A169: ROTHOBLAAS | B169: SKR | C169: Concrete screw hexagonal | D169: 2 | E169: 12 | F169: 160 | G169: 18 | L169: 100
A170: ROTHOBLAAS | B170: SKR | C170: Concrete screw hexagonal | D170: 2 | E170: 12 | F170: 140 | G170: 18 | L170: 100
A171: ROTHOBLAAS | B171: SKR | C171: Concrete screw hexagonal | D171: 2 | E171: 12 | F171: 120 | G171: 18 | L171: 100
A172: ROTHOBLAAS | B172: SKR | C172: Concrete screw hexagonal | D172: 2 | E172: 12 | F172: 100 | G172: 18 | L172: 100
A173: ROTHOBLAAS | B173: SKR | C173: Concrete screw hexagonal | D173: 2 | E173: 10 | F173: 160 | G173: 16 | L173: 95
A174: ROTHOBLAAS | B174: SKR | C174: Concrete screw hexagonal | D174: 2 | E174: 10 | F174: 140 | G174: 16 | L174: 95
A175: ROTHOBLAAS | B175: SKR | C175: Concrete screw hexagonal | D175: 2 | E175: 10 | F175: 120 | G175: 16 | L175: 95
... A192: ROTHOBLAAS | B192: SKSEVO | C192: Concrete screw countersunk | D192: 3 | E192: 7.5 | F192: 120 | G192: 13 | L192: 90
A193: ROTHOBLAAS | B193: VGS | C193: Fully threaded screw | D193: 2 | E193: 13 | F193: 1200 | G193: 22 | H193: 70.9 | I193: 11.7 | J193: 0 | K193: 53 | L193: =F193 -> 1200
...

Sheet Rothoblaas Bolts
A1: Produsent | B1: Type | C1: Usage | D1: Highest service class | E1: d | F1: l | G1: dh | H1: My,Rk [Nm] | I1: faxk[N/mm^2] | J1: fhead,k[N/mm^2] | K1: ftens,k[kN] | L1: fuk[N/mm2] | M1: fyk[N/mm2] | N1: def | O1: Aef
A2: ROTHOBLAAS | B2: EKS | C2: Hexagonal Head Bolt | E2: 24 | F2: 85 | G2: 39.98 | H2: =0.3*L2*N2^2.6/1000 -> 603.68846 | K2: 254.2 | L2: 800 | M2: =L2*0.8 -> 640 | N2: 20.32 | O2: =N2^2*PI()/4 -> 324.29279 | P2: =L2*O2/1000 -> 259.43423
A3: ROTHOBLAAS | B3: EKS | C3: Hexagonal Head Bolt | E3: 24 | F3: 80 | G3: 39.98 | H3: =0.3*L3*N3^2.6/1000 -> 603.68846 | K3: 254.2 | L3: 800 | M3: =L3*0.8 -> 640 | N3: 20.32 | O3: =N3^2*PI()/4 -> 324.29279 | P3: =L3*O3/1000 -> 259.43423
A4: ROTHOBLAAS | B4: EKS | C4: Hexagonal Head Bolt | E4: 24 | F4: 70 | G4: 39.98 | H4: =0.3*L4*N4^2.6/1000 -> 603.68846 | K4: 254.2 | L4: 800 | M4: =L4*0.8 -> 640 | N4: 20.32 | O4: =N4^2*PI()/4 -> 324.29279 | P4: =L4*O4/1000 -> 259.43423
A5: ROTHOBLAAS | B5: EKS | C5: Hexagonal Head Bolt | E5: 24 | F5: 65 | G5: 39.98 | H5: =0.3*L5*N5^2.6/1000 -> 603.68846 | K5: 254.2 | L5: 800 | M5: =L5*0.8 -> 640 | N5: 20.32 | O5: =N5^2*PI()/4 -> 324.29279 | P5: =L5*O5/1000 -> 259.43423
A6: ROTHOBLAAS | B6: EKS | C6: Hexagonal Head Bolt | E6: 24 | F6: 60 | G6: 39.98 | H6: =0.3*L6*N6^2.6/1000 -> 603.68846 | K6: 254.2 | L6: 800 | M6: =L6*0.8 -> 640 | N6: 20.32 | O6: =N6^2*PI()/4 -> 324.29279 | P6: =L6*O6/1000 -> 259.43423
A7: ROTHOBLAAS | B7: EKS | C7: Hexagonal Head Bolt | E7: 24 | F7: 50 | G7: 39.98 | H7: =0.3*L7*N7^2.6/1000 -> 603.68846 | K7: 254.2 | L7: 800 | M7: =L7*0.8 -> 640 | N7: 20.32 | O7: =N7^2*PI()/4 -> 324.29279 | P7: =L7*O7/1000 -> 259.43423
A8: ROTHOBLAAS | B8: EKS | C8: Hexagonal Head Bolt | E8: 24 | F8: 40 | G8: 39.98 | H8: =0.3*L8*N8^2.6/1000 -> 603.68846 | K8: 254.2 | L8: 800 | M8: =L8*0.8 -> 640 | N8: 20.32 | O8: =N8^2*PI()/4 -> 324.29279 | P8: =L8*O8/1000 -> 259.43423
A9: ROTHOBLAAS | B9: EKS | C9: Hexagonal Head Bolt | E9: 20 | F9: 100 | G9: 33.53 | H9: =0.3*L9*N9^2.6/1000 -> 375.59459 | K9: 176.4 | L9: 800 | M9: =L9*0.8 -> 640 | N9: 16.93 | O9: =N9^2*PI()/4 -> 225.11467 | P9: =L9*O9/1000 -> 180.09174
A10: ROTHOBLAAS | B10: EKS | C10: Hexagonal Head Bolt | E10: 20 | F10: 80 | G10: 33.53 | H10: =0.3*L10*N10^2.6/1000 -> 375.59459 | K10: 176.4 | L10: 800 | M10: =L10*0.8 -> 640 | N10: 16.93 | O10: =N10^2*PI()/4 -> 225.11467 | P10: =L10*O10/1000 -> 180.09174
A11: ROTHOBLAAS | B11: EKS | C11: Hexagonal Head Bolt | E11: 20 | F11: 70 | G11: 33.53 | H11: =0.3*L11*N11^2.6/1000 -> 375.59459 | K11: 176.4 | L11: 800 | M11: =L11*0.8 -> 640 | N11: 16.93 | O11: =N11^2*PI()/4 -> 225.11467 | P11: =L11*O11/1000 -> 180.09174
A12: ROTHOBLAAS | B12: EKS | C12: Hexagonal Head Bolt | E12: 20 | F12: 60 | G12: 33.53 | H12: =0.3*L12*N12^2.6/1000 -> 375.59459 | K12: 176.4 | L12: 800 | M12: =L12*0.8 -> 640 | N12: 16.93 | O12: =N12^2*PI()/4 -> 225.11467 | P12: =L12*O12/1000 -> 180.09174
A13: ROTHOBLAAS | B13: EKS | C13: Hexagonal Head Bolt | E13: 20 | F13: 50 | G13: 33.53 | H13: =0.3*L13*N13^2.6/1000 -> 375.59459 | K13: 176.4 | L13: 800 | M13: =L13*0.8 -> 640 | N13: 16.93 | O13: =N13^2*PI()/4 -> 225.11467 | P13: =L13*O13/1000 -> 180.09174
A14: ROTHOBLAAS | B14: EKS | C14: Hexagonal Head Bolt | E14: 20 | F14: 40 | G14: 33.53 | H14: =0.3*L14*N14^2.6/1000 -> 375.59459 | K14: 176.4 | L14: 800 | M14: =L14*0.8 -> 640 | N14: 16.93 | O14: =N14^2*PI()/4 -> 225.11467 | P14: =L14*O14/1000 -> 180.09174
A15: ROTHOBLAAS | B15: KOTA2 | C15: Round Head Bolt | D15: 3 | E15: 12 | F15: 300 | G15: 20.03 | H15: =0.3*L15*E15^2.6/1000 -> 76.745423 | K15: 30.3 | L15: 400 | M15: =L15*0.8 -> 320
A16: ROTHOBLAAS | B16: KOTA2 | C16: Round Head Bolt | D16: 3 | E16: 12 | F16: 280 | G16: 20.03 | H16: =0.3*L16*E16^2.6/1000 -> 76.745423 | K16: 30.3 | L16: 400 | M16: =L16*0.8 -> 320
A17: ROTHOBLAAS | B17: KOTA2 | C17: Round Head Bolt | D17: 3 | E17: 12 | F17: 240 | G17: 20.03 | H17: =0.3*L17*E17^2.6/1000 -> 76.745423 | K17: 30.3 | L17: 400 | M17: =L17*0.8 -> 320
A18: ROTHOBLAAS | B18: KOTA2 | C18: Round Head Bolt | D18: 3 | E18: 12 | F18: 220 | G18: 20.03 | H18: =0.3*L18*E18^2.6/1000 -> 76.745423 | K18: 30.3 | L18: 400 | M18: =L18*0.8 -> 320
A19: ROTHOBLAAS | B19: KOTA2 | C19: Round Head Bolt | D19: 3 | E19: 12 | F19: 200 | G19: 20.03 | H19: =0.3*L19*E19^2.6/1000 -> 76.745423 | K19: 30.3 | L19: 400 | M19: =L19*0.8 -> 320
A20: ROTHOBLAAS | B20: KOTA2 | C20: Round Head Bolt | D20: 3 | E20: 12 | F20: 180 | G20: 20.03 | H20: =0.3*L20*E20^2.6/1000 -> 76.745423 | K20: 30.3 | L20: 400 | M20: =L20*0.8 -> 320
A21: ROTHOBLAAS | B21: KOTA2 | C21: Round Head Bolt | D21: 3 | E21: 12 | F21: 160 | G21: 20.03 | H21: =0.3*L21*E21^2.6/1000 -> 76.745423 | K21: 30.3 | L21: 400 | M21: =L21*0.8 -> 320
A22: ROTHOBLAAS | B22: KOTA2 | C22: Round Head Bolt | D22: 3 | E22: 12 | F22: 140 | G22: 20.03 | H22: =0.3*L22*E22^2.6/1000 -> 76.745423 | K22: 30.3 | L22: 400 | M22: =L22*0.8 -> 320
A23: ROTHOBLAAS | B23: KOTA2 | C23: Round Head Bolt | D23: 3 | E23: 10 | F23: 220 | G23: 17.77 | H23: =0.3*L23*E23^2.6/1000 -> 47.77286 | K23: 20.9 | L23: 400 | M23: =L23*0.8 -> 320
A24: ROTHOBLAAS | B24: KOTA2 | C24: Round Head Bolt | D24: 3 | E24: 10 | F24: 200 | G24: 17.77 | H24: =0.3*L24*E24^2.6/1000 -> 47.77286 | K24: 20.9 | L24: 400 | M24: =L24*0.8 -> 320
A25: ROTHOBLAAS | B25: KOTA2 | C25: Round Head Bolt | D25: 3 | E25: 10 | F25: 180 | G25: 17.77 | H25: =0.3*L25*E25^2.6/1000 -> 47.77286 | K25: 20.9 | L25: 400 | M25: =L25*0.8 -> 320
A26: ROTHOBLAAS | B26: KOTA2 | C26: Round Head Bolt | D26: 3 | E26: 10 | F26: 160 | G26: 17.77 | H26: =0.3*L26*E26^2.6/1000 -> 47.77286 | K26: 20.9 | L26: 400 | M26: =L26*0.8 -> 320
... A61: ROTHOBLAAS | B61: KOT | C61: Round Head Bolt | D61: 1 | E61: 8 | F61: 50 | G61: 14.38 | H61: =0.3*L61*E61^2.6/1000 -> 26.743313 | K61: 13.2 | L61: 400 | M61: =L61*0.8 -> 320
A62: ROTHOBLAAS | B62: KOSA2 | C62: Hexagonal Head Bolt | D62: 3 | E62: 20 | F62: 400 | G62: 32.95 | H62: 579 | K62: 176.4 | L62: 800 | M62: =L62*0.8 -> 640
A63: ROTHOBLAAS | B63: KOSA2 | C63: Hexagonal Head Bolt | D63: 3 | E63: 20 | F63: 380 | G63: 32.95 | H63: 579 | K63: 176.4 | L63: 800 | M63: =L63*0.8 -> 640
A64: ROTHOBLAAS | B64: KOSA2 | C64: Hexagonal Head Bolt | D64: 3 | E64: 20 | F64: 360 | G64: 32.95 | H64: 579 | K64: 176.4 | L64: 800 | M64: =L64*0.8 -> 640
A65: ROTHOBLAAS | B65: KOSA2 | C65: Hexagonal Head Bolt | D65: 3 | E65: 20 | F65: 340 | G65: 32.95 | H65: 579 | K65: 176.4 | L65: 800 | M65: =L65*0.8 -> 640
A66: ROTHOBLAAS | B66: KOSA2 | C66: Hexagonal Head Bolt | D66: 3 | E66: 20 | F66: 320 | G66: 32.95 | H66: 579 | K66: 176.4 | L66: 800 | M66: =L66*0.8 -> 640
